Workbook

Sheet JOIN
A1: サブシス | B1: テーブル論理名 | C1: 決裁番号 | D1: オーダ番号 | E1: エントリ番号 | F1: 統一企業コード | G1: summit統一企業番号 | H1: s# | I1: サービスID(S#) | J1: サービスID | K1: b# | L1: 請求グループID(B#) | M1: 請求グループID | N1: c# | O1: 契約者ID(C#) | P1: 契約者ID | Q1: トランザクション番号
A2: BFSエントリ | B2: モバイル_サービスサマリ_付属品 | C2: =IFERROR(VLOOKUP(C$1, '(BFSエントリ)モバイル_サービスサマリ_付属品'!$C$9:$C$30, 1, FALSE), "") | D2: =IFERROR(VLOOKUP(D$1, '(BFSエントリ)モバイル_サービスサマリ_付属品'!$C$9:$C$30, 1, FALSE), "") | E2: =IFERROR(VLOOKUP(E$1, '(BFSエントリ)モバイル_サービスサマリ_付属品'!$C$9:$C$30, 1, FALSE), "") -> エントリ番号 | F2: =IFERROR(VLOOKUP(F$1, '(BFSエントリ)モバイル_サービスサマリ_付属品'!$C$9:$C$30, 1, FALSE), "") | G2: =IFERROR(VLOOKUP(G$1, '(BFSエントリ)モバイル_サービスサマリ_付属品'!$C$9:$C$30, 1, FALSE), "") | H2: =IFERROR(VLOOKUP(H$1, '(BFSエントリ)モバイル_サービスサマリ_付属品'!$C$9:$C$30, 1, FALSE), "") | I2: =IFERROR(VLOOKUP(I$1, '(BFSエントリ)モバイル_サービスサマリ_付属品'!$C$9:$C$30, 1, FALSE), "") | J2: =IFERROR(VLOOKUP(J$1, '(BFSエントリ)モバイル_サービスサマリ_付属品'!$C$9:$C$30, 1, FALSE), "") | ... Q2: =IFERROR(VLOOKUP(Q$1, '(BFSエントリ)モバイル_サービスサマリ_付属品'!$C$9:$C$30, 1, FALSE), "")
A3: BFSエントリ | B3: モバイル_サービスサマリ_端末 | C3: =IFERROR(VLOOKUP(C$1, '(BFSエントリ)モバイル_サービスサマリ_端末'!$C$9:$C$504, 1, FALSE),"") | D3: =IFERROR(VLOOKUP(D$1, '(BFSエントリ)モバイル_サービスサマリ_端末'!$C$9:$C$504, 1, FALSE),"") | E3: =IFERROR(VLOOKUP(E$1, '(BFSエントリ)モバイル_サービスサマリ_端末'!$C$9:$C$504, 1, FALSE),"") | F3: =IFERROR(VLOOKUP(F$1, '(BFSエントリ)モバイル_サービスサマリ_端末'!$C$9:$C$504, 1, FALSE),"") | G3: =IFERROR(VLOOKUP(G$1, '(BFSエントリ)モバイル_サービスサマリ_端末'!$C$9:$C$504, 1, FALSE),"") | H3: =IFERROR(VLOOKUP(H$1, '(BFSエントリ)モバイル_サービスサマリ_端末'!$C$9:$C$504, 1, FALSE),"") | I3: =IFERROR(VLOOKUP(I$1, '(BFSエントリ)モバイル_サービスサマリ_端末'!$C$9:$C$504, 1, FALSE),"") | J3: =IFERROR(VLOOKUP(J$1, '(BFSエントリ)モバイル_サービスサマリ_端末'!$C$9:$C$504, 1, FALSE),"") | ... Q3: =IFERROR(VLOOKUP(Q$1, '(BFSエントリ)モバイル_サービスサマリ_端末'!$C$9:$C$504, 1, FALSE),"")
A4: BFSエントリ | B4: モバイル_エントリ情報 | C4: =IFERROR(VLOOKUP(C$1, '(BFSエントリ)モバイル_エントリ情報'!$C$9:$C$224, 1, FALSE), "") | D4: =IFERROR(VLOOKUP(D$1, '(BFSエントリ)モバイル_エントリ情報'!$C$9:$C$224, 1, FALSE), "") | E4: =IFERROR(VLOOKUP(E$1, '(BFSエントリ)モバイル_エントリ情報'!$C$9:$C$224, 1, FALSE), "") -> エントリ番号 | F4: =IFERROR(VLOOKUP(F$1, '(BFSエントリ)モバイル_エントリ情報'!$C$9:$C$224, 1, FALSE), "") -> 統一企業コード | G4: =IFERROR(VLOOKUP(G$1, '(BFSエントリ)モバイル_エントリ情報'!$C$9:$C$224, 1, FALSE), "") | H4: =IFERROR(VLOOKUP(H$1, '(BFSエントリ)モバイル_エントリ情報'!$C$9:$C$224, 1, FALSE), "") | I4: =IFERROR(VLOOKUP(I$1, '(BFSエントリ)モバイル_エントリ情報'!$C$9:$C$224, 1, FALSE), "") | J4: =IFERROR(VLOOKUP(J$1, '(BFSエントリ)モバイル_エントリ情報'!$C$9:$C$224, 1, FALSE), "") | ... Q4: =IFERROR(VLOOKUP(Q$1, '(BFSエントリ)モバイル_エントリ情報'!$C$9:$C$224, 1, FALSE), "")
A5: RMS | B5: 契約基本情報 | C5: =IFERROR(VLOOKUP(C$1, '(RMS)契約基本情報'!$C$9:$C$999, 1, FALSE), "") | D5: =IFERROR(VLOOKUP(D$1, '(RMS)契約基本情報'!$C$9:$C$999, 1, FALSE), "") -> オーダ番号 | E5: =IFERROR(VLOOKUP(E$1, '(RMS)契約基本情報'!$C$9:$C$999, 1, FALSE), "") | F5: =IFERROR(VLOOKUP(F$1, '(RMS)契約基本情報'!$C$9:$C$999, 1, FALSE), "") | G5: =IFERROR(VLOOKUP(G$1, '(RMS)契約基本情報'!$C$9:$C$999, 1, FALSE), "") -> summit統一企業番号 | H5: =IFERROR(VLOOKUP(H$1, '(RMS)契約基本情報'!$C$9:$C$999, 1, FALSE), "") -> s# | I5: =IFERROR(VLOOKUP(I$1, '(RMS)契約基本情報'!$C$9:$C$999, 1, FALSE), "") | J5: =IFERROR(VLOOKUP(J$1, '(RMS)契約基本情報'!$C$9:$C$999, 1, FALSE), "") | ... Q5: =IFERROR(VLOOKUP(Q$1, '(RMS)契約基本情報'!$C$9:$C$999, 1, FALSE), "")
A6: RMS | B6: 契約料金情報 | C6: =IFERROR(VLOOKUP(C$1, '(RMS)契約料金情報'!$C$9:$C$999, 1, FALSE), "") -> 決裁番号 | D6: =IFERROR(VLOOKUP(D$1, '(RMS)契約料金情報'!$C$9:$C$999, 1, FALSE), "") -> オーダ番号 | E6: =IFERROR(VLOOKUP(E$1, '(RMS)契約料金情報'!$C$9:$C$999, 1, FALSE), "") | F6: =IFERROR(VLOOKUP(F$1, '(RMS)契約料金情報'!$C$9:$C$999, 1, FALSE), "") | G6: =IFERROR(VLOOKUP(G$1, '(RMS)契約料金情報'!$C$9:$C$999, 1, FALSE), "") | H6: =IFERROR(VLOOKUP(H$1, '(RMS)契約料金情報'!$C$9:$C$999, 1, FALSE), "") | I6: =IFERROR(VLOOKUP(I$1, '(RMS)契約料金情報'!$C$9:$C$999, 1, FALSE), "") | J6: =IFERROR(VLOOKUP(J$1, '(RMS)契約料金情報'!$C$9:$C$999, 1, FALSE), "") | ... Q6: =IFERROR(VLOOKUP(Q$1, '(RMS)契約料金情報'!$C$9:$C$999, 1, FALSE), "")
A7: COP | B7: 支払情報 | C7: =IFERROR(VLOOKUP(C$1, '(COP)支払情報'!$C$9:$C$999, 1, FALSE), "") | D7: =IFERROR(VLOOKUP(D$1, '(COP)支払情報'!$C$9:$C$999, 1, FALSE), "") | E7: =IFERROR(VLOOKUP(E$1, '(COP)支払情報'!$C$9:$C$999, 1, FALSE), "") | F7: =IFERROR(VLOOKUP(F$1, '(COP)支払情報'!$C$9:$C$999, 1, FALSE), "") | G7: =IFERROR(VLOOKUP(G$1, '(COP)支払情報'!$C$9:$C$999, 1, FALSE), "") | H7: =IFERROR(VLOOKUP(H$1, '(COP)支払情報'!$C$9:$C$999, 1, FALSE), "") | I7: =IFERROR(VLOOKUP(I$1, '(COP)支払情報'!$C$9:$C$999, 1, FALSE), "") | J7: =IFERROR(VLOOKUP(J$1, '(COP)支払情報'!$C$9:$C$999, 1, FALSE), "") | ... Q7: =IFERROR(VLOOKUP(Q$1, '(COP)支払情報'!$C$9:$C$999, 1, FALSE), "")
A8: COP | B8: 契約者リンク履歴 | C8: =IFERROR(VLOOKUP(C$1, '(COP)契約者リンク履歴'!$H$9:$H$999, 1, FALSE), "") | D8: =IFERROR(VLOOKUP(D$1, '(COP)契約者リンク履歴'!$H$9:$H$999, 1, FALSE), "") | E8: =IFERROR(VLOOKUP(E$1, '(COP)契約者リンク履歴'!$H$9:$H$999, 1, FALSE), "") | F8: =IFERROR(VLOOKUP(F$1, '(COP)契約者リンク履歴'!$H$9:$H$999, 1, FALSE), "") | G8: =IFERROR(VLOOKUP(G$1, '(COP)契約者リンク履歴'!$H$9:$H$999, 1, FALSE), "") | H8: =IFERROR(VLOOKUP(H$1, '(COP)契約者リンク履歴'!$H$9:$H$999, 1, FALSE), "") | I8: =IFERROR(VLOOKUP(I$1, '(COP)契約者リンク履歴'!$H$9:$H$999, 1, FALSE), "") -> サービスID(S#) | J8: =IFERROR(VLOOKUP(J$1, '(COP)契約者リンク履歴'!$H$9:$H$999, 1, FALSE), "") | ... Q8: =IFERROR(VLOOKUP(Q$1, '(COP)契約者リンク履歴'!$H$9:$H$999, 1, FALSE), "")
A9: COP | B9: svcリンク履歴 | C9: =IFERROR(VLOOKUP(C$1, '(COP)svcリンク履歴'!$H$9:$H$999, 1, FALSE), "") | D9: =IFERROR(VLOOKUP(D$1, '(COP)svcリンク履歴'!$H$9:$H$999, 1, FALSE), "") | E9: =IFERROR(VLOOKUP(E$1, '(COP)svcリンク履歴'!$H$9:$H$999, 1, FALSE), "") | F9: =IFERROR(VLOOKUP(F$1, '(COP)svcリンク履歴'!$H$9:$H$999, 1, FALSE), "") | G9: =IFERROR(VLOOKUP(G$1, '(COP)svcリンク履歴'!$H$9:$H$999, 1, FALSE), "") | H9: =IFERROR(VLOOKUP(H$1, '(COP)svcリンク履歴'!$H$9:$H$999, 1, FALSE), "") | I9: =IFERROR(VLOOKUP(I$1, '(COP)svcリンク履歴'!$H$9:$H$999, 1, FALSE), "") -> サービスID(S#) | J9: =IFERROR(VLOOKUP(J$1, '(COP)svcリンク履歴'!$H$9:$H$999, 1, FALSE), "") | ... Q9: =IFERROR(VLOOKUP(Q$1, '(COP)svcリンク履歴'!$H$9:$H$999, 1, FALSE), "") -> トランザクション番号
A10: COP | B10: 販売履歴 | C10: =IFERROR(VLOOKUP(C$1, '(COP)販売履歴'!$H$9:$H$999, 1, FALSE), "") | D10: =IFERROR(VLOOKUP(D$1, '(COP)販売履歴'!$H$9:$H$999, 1, FALSE), "") | E10: =IFERROR(VLOOKUP(E$1, '(COP)販売履歴'!$H$9:$H$999, 1, FALSE), "") | F10: =IFERROR(VLOOKUP(F$1, '(COP)販売履歴'!$H$9:$H$999, 1, FALSE), "") | G10: =IFERROR(VLOOKUP(G$1, '(COP)販売履歴'!$H$9:$H$999, 1, FALSE), "") | H10: =IFERROR(VLOOKUP(H$1, '(COP)販売履歴'!$H$9:$H$999, 1, FALSE), "") | I10: =IFERROR(VLOOKUP(I$1, '(COP)販売履歴'!$H$9:$H$999, 1, FALSE), "") -> サービスID(S#) | J10: =IFERROR(VLOOKUP(J$1, '(COP)販売履歴'!$H$9:$H$999, 1, FALSE), "") | ... Q10: =IFERROR(VLOOKUP(Q$1, '(COP)販売履歴'!$H$9:$H$999, 1, FALSE), "")
A11: COP | B11: 機器割当 | C11: =IFERROR(VLOOKUP(C$1, '(COP)機器割当'!$H$9:$H$999, 1, FALSE), "") | D11: =IFERROR(VLOOKUP(D$1, '(COP)機器割当'!$H$9:$H$999, 1, FALSE), "") | E11: =IFERROR(VLOOKUP(E$1, '(COP)機器割当'!$H$9:$H$999, 1, FALSE), "") | F11: =IFERROR(VLOOKUP(F$1, '(COP)機器割当'!$H$9:$H$999, 1, FALSE), "") | G11: =IFERROR(VLOOKUP(G$1, '(COP)機器割当'!$H$9:$H$999, 1, FALSE), "") | H11: =IFERROR(VLOOKUP(H$1, '(COP)機器割当'!$H$9:$H$999, 1, FALSE), "") | I11: =IFERROR(VLOOKUP(I$1, '(COP)機器割当'!$H$9:$H$999, 1, FALSE), "") -> サービスID(S#) | J11: =IFERROR(VLOOKUP(J$1, '(COP)機器割当'!$H$9:$H$999, 1, FALSE), "") | ... Q11: =IFERROR(VLOOKUP(Q$1, '(COP)機器割当'!$H$9:$H$999, 1, FALSE), "") -> トランザクション番号
A12: COP | B12: プロダクト | C12: =IFERROR(VLOOKUP(C$1, '(COP)プロダクト'!$H$9:$H$999, 1, FALSE), "") | D12: =IFERROR(VLOOKUP(D$1, '(COP)プロダクト'!$H$9:$H$999, 1, FALSE), "") | E12: =IFERROR(VLOOKUP(E$1, '(COP)プロダクト'!$H$9:$H$999, 1, FALSE), "") | F12: =IFERROR(VLOOKUP(F$1, '(COP)プロダクト'!$H$9:$H$999, 1, FALSE), "") | G12: =IFERROR(VLOOKUP(G$1, '(COP)プロダクト'!$H$9:$H$999, 1, FALSE), "") | H12: =IFERROR(VLOOKUP(H$1, '(COP)プロダクト'!$H$9:$H$999, 1, FALSE), "") | I12: =IFERROR(VLOOKUP(I$1, '(COP)プロダクト'!$H$9:$H$999, 1, FALSE), "") | J12: =IFERROR(VLOOKUP(J$1, '(COP)プロダクト'!$H$9:$H$999, 1, FALSE), "") | ... Q12: =IFERROR(VLOOKUP(Q$1, '(COP)プロダクト'!$H$9:$H$999, 1, FALSE), "") -> トランザクション番号
A13: Mars | B13: 取次店 | C13: =IFERROR(VLOOKUP(C$1, '(Mars)取次店'!$C$9:$C$999, 1, FALSE), "") | D13: =IFERROR(VLOOKUP(D$1, '(Mars)取次店'!$C$9:$C$999, 1, FALSE), "") | E13: =IFERROR(VLOOKUP(E$1, '(Mars)取次店'!$C$9:$C$999, 1, FALSE), "") | F13: =IFERROR(VLOOKUP(F$1, '(Mars)取次店'!$C$9:$C$999, 1, FALSE), "") | G13: =IFERROR(VLOOKUP(G$1, '(Mars)取次店'!$C$9:$C$999, 1, FALSE), "") | H13: =IFERROR(VLOOKUP(H$1, '(Mars)取次店'!$C$9:$C$999, 1, FALSE), "") | I13: =IFERROR(VLOOKUP(I$1, '(Mars)取次店'!$C$9:$C$999, 1, FALSE), "") | J13: =IFERROR(VLOOKUP(J$1, '(Mars)取次店'!$C$9:$C$999, 1, FALSE), "") | ... Q13: =IFERROR(VLOOKUP(Q$1, '(Mars)取次店'!$C$9:$C$999, 1, FALSE), "")
A14: Mars | B14: キャンペーン | C14: =IFERROR(VLOOKUP(C$1, '(Mars)キャンペーン'!$C$9:$C$999, 1, FALSE), "") | D14: =IFERROR(VLOOKUP(D$1, '(Mars)キャンペーン'!$C$9:$C$999, 1, FALSE), "") | E14: =IFERROR(VLOOKUP(E$1, '(Mars)キャンペーン'!$C$9:$C$999, 1, FALSE), "") | F14: =IFERROR(VLOOKUP(F$1, '(Mars)キャンペーン'!$C$9:$C$999, 1, FALSE), "") | G14: =IFERROR(VLOOKUP(G$1, '(Mars)キャンペーン'!$C$9:$C$999, 1, FALSE), "") | H14: =IFERROR(VLOOKUP(H$1, '(Mars)キャンペーン'!$C$9:$C$999, 1, FALSE), "") | I14: =IFERROR(VLOOKUP(I$1, '(Mars)キャンペーン'!$C$9:$C$999, 1, FALSE), "") | J14: =IFERROR(VLOOKUP(J$1, '(Mars)キャンペーン'!$C$9:$C$999, 1, FALSE), "") | ... Q14: =IFERROR(VLOOKUP(Q$1, '(Mars)キャンペーン'!$C$9:$C$999, 1, FALSE), "")
A15: Mars | B15: 商品 | C15: =IFERROR(VLOOKUP(C$1, '(Mars)商品'!$C$9:$C$999, 1, FALSE), "") | D15: =IFERROR(VLOOKUP(D$1, '(Mars)商品'!$C$9:$C$999, 1, FALSE), "") | E15: =IFERROR(VLOOKUP(E$1, '(Mars)商品'!$C$9:$C$999, 1, FALSE), "") | F15: =IFERROR(VLOOKUP(F$1, '(Mars)商品'!$C$9:$C$999, 1, FALSE), "") | G15: =IFERROR(VLOOKUP(G$1, '(Mars)商品'!$C$9:$C$999, 1, FALSE), "") | H15: =IFERROR(VLOOKUP(H$1, '(Mars)商品'!$C$9:$C$999, 1, FALSE), "") | I15: =IFERROR(VLOOKUP(I$1, '(Mars)商品'!$C$9:$C$999, 1, FALSE), "") | J15: =IFERROR(VLOOKUP(J$1, '(Mars)商品'!$C$9:$C$999, 1, FALSE), "") | ... Q15: =IFERROR(VLOOKUP(Q$1, '(Mars)商品'!$C$9:$C$999, 1, FALSE), "")
A16: SUMMIT | B16: 決裁_料金決裁 | C16: =IFERROR(VLOOKUP(C$1, '(SUMMIT)決裁_料金決裁'!$C$9:$C$999, 1, FALSE), "") -> 決裁番号 | D16: =IFERROR(VLOOKUP(D$1, '(SUMMIT)決裁_料金決裁'!$C$9:$C$999, 1, FALSE), "") | E16: =IFERROR(VLOOKUP(E$1, '(SUMMIT)決裁_料金決裁'!$C$9:$C$999, 1, FALSE), "") | F16: =IFERROR(VLOOKUP(F$1, '(SUMMIT)決裁_料金決裁'!$C$9:$C$999, 1, FALSE), "") | G16: =IFERROR(VLOOKUP(G$1, '(SUMMIT)決裁_料金決裁'!$C$9:$C$999, 1, FALSE), "") | H16: =IFERROR(VLOOKUP(H$1, '(SUMMIT)決裁_料金決裁'!$C$9:$C$999, 1, FALSE), "") | I16: =IFERROR(VLOOKUP(I$1, '(SUMMIT)決裁_料金決裁'!$C$9:$C$999, 1, FALSE), "") | J16: =IFERROR(VLOOKUP(J$1, '(SUMMIT)決裁_料金決裁'!$C$9:$C$999, 1, FALSE), "") | ... Q16: =IFERROR(VLOOKUP(Q$1, '(SUMMIT)決裁_料金決裁'!$C$9:$C$999, 1, FALSE), "")
A17: SUMMIT | B17: 決裁_提案モバイル | C17: =IFERROR(VLOOKUP(C$1, '(SUMMIT)決裁_提案モバイル'!$C$9:$C$999, 1, FALSE), "") -> 決裁番号 | D17: =IFERROR(VLOOKUP(D$1, '(SUMMIT)決裁_提案モバイル'!$C$9:$C$999, 1, FALSE), "") | E17: =IFERROR(VLOOKUP(E$1, '(SUMMIT)決裁_提案モバイル'!$C$9:$C$999, 1, FALSE), "") | F17: =IFERROR(VLOOKUP(F$1, '(SUMMIT)決裁_提案モバイル'!$C$9:$C$999, 1, FALSE), "") | G17: =IFERROR(VLOOKUP(G$1, '(SUMMIT)決裁_提案モバイル'!$C$9:$C$999, 1, FALSE), "") | H17: =IFERROR(VLOOKUP(H$1, '(SUMMIT)決裁_提案モバイル'!$C$9:$C$999, 1, FALSE), "") | I17: =IFERROR(VLOOKUP(I$1, '(SUMMIT)決裁_提案モバイル'!$C$9:$C$999, 1, FALSE), "") | J17: =IFERROR(VLOOKUP(J$1, '(SUMMIT)決裁_提案モバイル'!$C$9:$C$999, 1, FALSE), "") | ... M17: =IFERROR(VLOOKUP(M$1, '(SUMMIT)決裁_提案モバイル'!$C$9:$C$999, 1, FALSE), "") | Q17: =IFERROR(VLOOKUP(Q$1, '(SUMMIT)決裁_提案モバイル'!$C$9:$C$999, 1, FALSE), "")
A18: SUMMIT | B18: 決裁_共通決裁 | C18: =IFERROR(VLOOKUP(C$1, '(SUMMIT)決裁_共通決裁'!$C$9:$C$999, 1, FALSE), "") -> 決裁番号 | D18: =IFERROR(VLOOKUP(D$1, '(SUMMIT)決裁_共通決裁'!$C$9:$C$999, 1, FALSE), "") | E18: =IFERROR(VLOOKUP(E$1, '(SUMMIT)決裁_共通決裁'!$C$9:$C$999, 1, FALSE), "") | F18: =IFERROR(VLOOKUP(F$1, '(SUMMIT)決裁_共通決裁'!$C$9:$C$999, 1, FALSE), "") | G18: =IFERROR(VLOOKUP(G$1, '(SUMMIT)決裁_共通決裁'!$C$9:$C$999, 1, FALSE), "") | H18: =IFERROR(VLOOKUP(H$1, '(SUMMIT)決裁_共通決裁'!$C$9:$C$999, 1, FALSE), "") | I18: =IFERROR(VLOOKUP(I$1, '(SUMMIT)決裁_共通決裁'!$C$9:$C$999, 1, FALSE), "") | J18: =IFERROR(VLOOKUP(J$1, '(SUMMIT)決裁_共通決裁'!$C$9:$C$999, 1, FALSE), "") | ... Q18: =IFERROR(VLOOKUP(Q$1, '(SUMMIT)決裁_共通決裁'!$C$9:$C$999, 1, FALSE), "")
A19: SUMMIT | B19: 決裁_基本_補足 | C19: =IFERROR(VLOOKUP(C$1, '(SUMMIT)決裁_基本_補足'!$C$9:$C$999, 1, FALSE), "") -> 決裁番号 | D19: =IFERROR(VLOOKUP(D$1, '(SUMMIT)決裁_基本_補足'!$C$9:$C$999, 1, FALSE), "") | E19: =IFERROR(VLOOKUP(E$1, '(SUMMIT)決裁_基本_補足'!$C$9:$C$999, 1, FALSE), "") | F19: =IFERROR(VLOOKUP(F$1, '(SUMMIT)決裁_基本_補足'!$C$9:$C$999, 1, FALSE), "") -> 統一企業コード | G19: =IFERROR(VLOOKUP(G$1, '(SUMMIT)決裁_基本_補足'!$C$9:$C$999, 1, FALSE), "") | H19: =IFERROR(VLOOKUP(H$1, '(SUMMIT)決裁_基本_補足'!$C$9:$C$999, 1, FALSE), "") | I19: =IFERROR(VLOOKUP(I$1, '(SUMMIT)決裁_基本_補足'!$C$9:$C$999, 1, FALSE), "") | J19: =IFERROR(VLOOKUP(J$1, '(SUMMIT)決裁_基本_補足'!$C$9:$C$999, 1, FALSE), "") | ... Q19: =IFERROR(VLOOKUP(Q$1, '(SUMMIT)決裁_基本_補足'!$C$9:$C$999, 1, FALSE), "")
A20: SUMMIT | B20: 決裁_関連申請書 | C20: =IFERROR(VLOOKUP(C$1, '(SUMMIT)決裁_関連申請書'!$C$9:$C$999, 1, FALSE), "") | D20: =IFERROR(VLOOKUP(D$1, '(SUMMIT)決裁_関連申請書'!$C$9:$C$999, 1, FALSE), "") | E20: =IFERROR(VLOOKUP(E$1, '(SUMMIT)決裁_関連申請書'!$C$9:$C$999, 1, FALSE), "") | F20: =IFERROR(VLOOKUP(F$1, '(SUMMIT)決裁_関連申請書'!$C$9:$C$999, 1, FALSE), "") | G20: =IFERROR(VLOOKUP(G$1, '(SUMMIT)決裁_関連申請書'!$C$9:$C$999, 1, FALSE), "") | H20: =IFERROR(VLOOKUP(H$1, '(SUMMIT)決裁_関連申請書'!$C$9:$C$999, 1, FALSE), "") | I20: =IFERROR(VLOOKUP(I$1, '(SUMMIT)決裁_関連申請書'!$C$9:$C$999, 1, FALSE), "") | J20: =IFERROR(VLOOKUP(J$1, '(SUMMIT)決裁_関連申請書'!$C$9:$C$999, 1, FALSE), "") | ... Q20: =IFERROR(VLOOKUP(Q$1, '(SUMMIT)決裁_関連申請書'!$C$9:$C$999, 1, FALSE), "")

Sheet メモ

Sheet (BFSエントリ)モバイル_サービスサマリ_付属品
G2: 種別 | H2: DWH公開名 | I2: 旧DWH公開名 | J2: 統合テーブルID | K2: スキーマ
G3: ビュー | H3: b_hjn_bfs_モバイル_サービスサマリ_付属品 | J3: V004659 | K3: user_l2_prvl | L3: bfs_service_summary_accessories
G4: データ概要：
G5: 0
K6: ="DROP TABLE IF EXISTS "&L3&" CASCADE;" -> DROP TABLE IF EXISTS bfs_service_summary_accessories CASCADE; | R6: DROP TABLE IF EXISTS bfs_service_summary_accessories CASCADE;
K7: ="CREATE TABLE IF NOT EXISTS "&L3&" (" -> CREATE TABLE IF NOT EXISTS bfs_service_summary_accessories ( | N7: ="COMMENT ON TABLE "&L3&" IS '"&H3&"';" -> COMMENT ON TABLE bfs_service_summary_accessories IS 'b_hjn_bfs_モバイル_サービスサマリ_付属品'; | R7: CREATE TABLE IF NOT EXISTS bfs_service_summary_accessories (
A8: pk | B8: SEQ | C8: 項目名 | D8: TYPE | E8: 桁 | F8: 仮名化 | G8: 項目説明およびリスト値 | H8: コードリファレンスリンク | I8: 備考 | J8: 更新日 | K8: id BIGINT GENERATED BY DEFAULT AS IDENTITY, | N8: ="COMMENT ON COLUMN "&$L$3&".id IS '"&C8&"';" -> COMMENT ON COLUMN bfs_service_summary_accessories.id IS '項目名'; | R8: id BIGINT GENERATED BY DEFAULT AS IDENTITY,
B9: 1 | C9: エントリ番号 | D9: VARCHAR | E9: 54 | F9: － | K9: entry_number | L9: =D9&"("&E9&")," -> VARCHAR(54), | N9: ="COMMENT ON COLUMN "&$L$3&"."&K9&" IS '"&C9&"';" -> COMMENT ON COLUMN bfs_service_summary_accessories.entry_number IS 'エントリ番号'; | R9: entry_number VARCHAR(54),
B10: 2 | C10: サマリ番号 | D10: VARCHAR | E10: 36 | F10: － | K10: summary_number | L10: =D10&"("&E10&")," -> VARCHAR(36), | N10: ="COMMENT ON COLUMN "&$L$3&"."&K10&" IS '"&C10&"';" -> COMMENT ON COLUMN bfs_service_summary_accessories.summary_number IS 'サマリ番号'; | R10: summary_number VARCHAR(36),
B11: 3 | C11: シリアル付付属品 | D11: VARCHAR | E11: 2295 | F11: － | K11: serial_number_accessories | L11: =D11&"("&E11&")," -> VARCHAR(2295), | N11: ="COMMENT ON COLUMN "&$L$3&"."&K11&" IS '"&C11&"';" -> COMMENT ON COLUMN bfs_service_summary_accessories.serial_number_accessories IS 'シリアル付付属品'; | R11: serial_number_accessories VARCHAR(2295),
B12: 4 | C12: 商品コード | D12: VARCHAR | E12: 45 | F12: － | K12: product_code | L12: =D12&"("&E12&")," -> VARCHAR(45), | N12: ="COMMENT ON COLUMN "&$L$3&"."&K12&" IS '"&C12&"';" -> COMMENT ON COLUMN bfs_service_summary_accessories.product_code IS '商品コード'; | R12: product_code VARCHAR(45),
B13: 5 | C13: メーカ | D13: VARCHAR | E13: 1800 | F13: － | K13: manufacturer | L13: =D13&"("&E13&")," -> VARCHAR(1800), | N13: ="COMMENT ON COLUMN "&$L$3&"."&K13&" IS '"&C13&"';" -> COMMENT ON COLUMN bfs_service_summary_accessories.manufacturer IS 'メーカ'; | R13: manufacturer VARCHAR(1800),
B14: 6 | C14: 商品名 | D14: VARCHAR | E14: 900 | F14: － | K14: product_name | L14: =D14&"("&E14&")," -> VARCHAR(900), | N14: ="COMMENT ON COLUMN "&$L$3&"."&K14&" IS '"&C14&"';" -> COMMENT ON COLUMN bfs_service_summary_accessories.product_name IS '商品名'; | R14: product_name VARCHAR(900),
B15: 7 | C15: カラー1 | D15: VARCHAR | E15: 900 | F15: － | K15: color_1 | L15: =D15&"("&E15&")," -> VARCHAR(900), | N15: ="COMMENT ON COLUMN "&$L$3&"."&K15&" IS '"&C15&"';" -> COMMENT ON COLUMN bfs_service_summary_accessories.color_1 IS 'カラー1'; | R15: color_1 VARCHAR(900),
B16: 8 | C16: 台数1 | D16: DECIMAL | E16: 6 | F16: － | K16: quantity_1 | L16: =D16&"("&E16&")," -> DECIMAL(6), | N16: ="COMMENT ON COLUMN "&$L$3&"."&K16&" IS '"&C16&"';" -> COMMENT ON COLUMN bfs_service_summary_accessories.quantity_1 IS '台数1'; | R16: quantity_1 DECIMAL(6),
B17: 9 | C17: カラー2 | D17: VARCHAR | E17: 900 | F17: － | K17: color_2 | L17: =D17&"("&E17&")," -> VARCHAR(900), | N17: ="COMMENT ON COLUMN "&$L$3&"."&K17&" IS '"&C17&"';" -> COMMENT ON COLUMN bfs_service_summary_accessories.color_2 IS 'カラー2'; | R17: color_2 VARCHAR(900),
B18: 10 | C18: 台数2 | D18: DECIMAL | E18: 6 | F18: － | K18: quantity_2 | L18: =D18&"("&E18&")," -> DECIMAL(6), | N18: ="COMMENT ON COLUMN "&$L$3&"."&K18&" IS '"&C18&"';" -> COMMENT ON COLUMN bfs_service_summary_accessories.quantity_2 IS '台数2'; | R18: quantity_2 DECIMAL(6),
B19: 11 | C19: カラー3 | D19: VARCHAR | E19: 900 | F19: － | K19: color_3 | L19: =D19&"("&E19&")," -> VARCHAR(900), | N19: ="COMMENT ON COLUMN "&$L$3&"."&K19&" IS '"&C19&"';" -> COMMENT ON COLUMN bfs_service_summary_accessories.color_3 IS 'カラー3'; | R19: color_3 VARCHAR(900),
B20: 12 | C20: 台数3 | D20: DECIMAL | E20: 6 | F20: － | K20: quantity_3 | L20: =D20&"("&E20&")," -> DECIMAL(6), | N20: ="COMMENT ON COLUMN "&$L$3&"."&K20&" IS '"&C20&"';" -> COMMENT ON COLUMN bfs_service_summary_accessories.quantity_3 IS '台数3'; | R20: quantity_3 DECIMAL(6),
... B29: 21 | C29: 紐付けサマリ番号 | D29: VARCHAR | E29: 90 | F29: － | K29: linked_summary_number | L29: =D29&"("&E29&")," -> VARCHAR(90), | N29: ="COMMENT ON COLUMN "&$L$3&"."&K29&" IS '"&C29&"';" -> COMMENT ON COLUMN bfs_service_summary_accessories.linked_summary_number IS '紐付けサマリ番号'; | R29: linked_summary_number VARCHAR(90),
B30: 22 | C30: 原価予備費 | D30: DECIMAL | E30: 8,0 | F30: － | K30: cost_contingency | L30: =D30&"("&E30&")," -> DECIMAL(8,0), | N30: ="COMMENT ON COLUMN "&$L$3&"."&K30&" IS '"&C30&"';" -> COMMENT ON COLUMN bfs_service_summary_accessories.cost_contingency IS '原価予備費'; | R30: cost_contingency DECIMAL(8,0),
K31: ="CONSTRAINT pk_"&L3&" PRIMARY KEY (id));" -> CONSTRAINT pk_bfs_service_summary_accessories PRIMARY KEY (id)); | R31: CONSTRAINT pk_bfs_service_summary_accessories PRIMARY KEY (id));
R32: COMMENT ON TABLE bfs_service_summary_accessories IS 'b_hjn_bfs_モバイル_サービスサマリ_付属品';
R33: COMMENT ON COLUMN bfs_service_summary_accessories.id IS '項目名';
R34: COMMENT ON COLUMN bfs_service_summary_accessories.entry_number IS 'エントリ番号';
R35: COMMENT ON COLUMN bfs_service_summary_accessories.summary_number IS 'サマリ番号';
R36: COMMENT ON COLUMN bfs_service_summary_accessories.serial_number_accessories IS 'シリアル付付属品';
R37: COMMENT ON COLUMN bfs_service_summary_accessories.product_code IS '商品コード';
R38: COMMENT ON COLUMN bfs_service_summary_accessories.manufacturer IS 'メーカ';
R39: COMMENT ON COLUMN bfs_service_summary_accessories.product_name IS '商品名';
R40: COMMENT ON COLUMN bfs_service_summary_accessories.color_1 IS 'カラー1';
R41: COMMENT ON COLUMN bfs_service_summary_accessories.quantity_1 IS '台数1';
R42: COMMENT ON COLUMN bfs_service_summary_accessories.color_2 IS 'カラー2';
R43: COMMENT ON COLUMN bfs_service_summary_accessories.quantity_2 IS '台数2';
... R55: COMMENT ON COLUMN bfs_service_summary_accessories.cost_contingency IS '原価予備費';

Sheet (BFSエントリ)モバイル_サービスサマリ_端末
C2: 種別 | D2: DWH公開名 | E2: 旧DWH公開名 | F2: 統合テーブルID | G2: スキーマ
C3: ビュー | D3: b_hjn_bfs_モバイル_サービスサマリ_端末 | F3: V004515 | G3: user_l2_prvl | H3: bfs_service_summary_device
K4: ="DROP TABLE IF EXISTS "&H3&" CASCADE;" -> DROP TABLE IF EXISTS bfs_service_summary_device CASCADE; | R4: DROP TABLE IF EXISTS bfs_service_summary_device CASCADE;
K5: ="CREATE TABLE IF NOT EXISTS "&H3&" (" -> CREATE TABLE IF NOT EXISTS bfs_service_summary_device ( | N5: ="COMMENT ON TABLE "&H3&" IS '"&D3&"';" -> COMMENT ON TABLE bfs_service_summary_device IS 'b_hjn_bfs_モバイル_サービスサマリ_端末'; | R5: CREATE TABLE IF NOT EXISTS bfs_service_summary_device (
A6: pk | B6: SEQ | C6: 項目名 | D6: TYPE | E6: 桁 | F6: 仮名化 | G6: 項目説明およびリスト値 | H6: コードリファレンスリンク | I6: 備考 | J6: 更新日 | K6: id BIGINT GENERATED BY DEFAULT AS IDENTITY, | N6: ="COMMENT ON COLUMN "&$H$3&".id IS 'id';" -> COMMENT ON COLUMN bfs_service_summary_device.id IS 'id'; | R6: id BIGINT GENERATED BY DEFAULT AS IDENTITY,
B7: 1 | C7: エントリ番号 | D7: VARCHAR | E7: 54 | F7: － | K7: entry_number | L7: =D7&"("&E7&")," -> VARCHAR(54), | N7: ="COMMENT ON COLUMN "&$H$3&"."&$K7&" IS '"&C7&"';" -> COMMENT ON COLUMN bfs_service_summary_device.entry_number IS 'エントリ番号'; | R7: entry_number VARCHAR(54),
B8: 2 | C8: サマリ番号 | D8: VARCHAR | E8: 36 | F8: － | K8: summary_number | L8: =D8&"("&E8&")," -> VARCHAR(36), | N8: ="COMMENT ON COLUMN "&$H$3&"."&$K8&" IS '"&C8&"';" -> COMMENT ON COLUMN bfs_service_summary_device.summary_number IS 'サマリ番号'; | R8: summary_number VARCHAR(36),
B9: 3 | C9: 回線数 | D9: DECIMAL | E9: 10 | F9: － | K9: number_of_lines | L9: =D9&"("&E9&")," -> DECIMAL(10), | N9: ="COMMENT ON COLUMN "&$H$3&"."&$K9&" IS '"&C9&"';" -> COMMENT ON COLUMN bfs_service_summary_device.number_of_lines IS '回線数'; | R9: number_of_lines DECIMAL(10),
B10: 4 | C10: レンタルセット端末 | D10: VARCHAR | E10: 2295 | F10: － | K10: rental_set_device | L10: =D10&"("&E10&")," -> VARCHAR(2295), | N10: ="COMMENT ON COLUMN "&$H$3&"."&$K10&" IS '"&C10&"';" -> COMMENT ON COLUMN bfs_service_summary_device.rental_set_device IS 'レンタルセット端末'; | R10: rental_set_device VARCHAR(2295),
B11: 5 | C11: mnp | D11: VARCHAR | E11: 2295 | F11: － | K11: mnp | L11: =D11&"("&E11&")," -> VARCHAR(2295), | N11: ="COMMENT ON COLUMN "&$H$3&"."&$K11&" IS '"&C11&"';" -> COMMENT ON COLUMN bfs_service_summary_device.mnp IS 'mnp'; | R11: mnp VARCHAR(2295),
B12: 6 | C12: 商品コード | D12: VARCHAR | E12: 45 | F12: － | K12: product_code | L12: =D12&"("&E12&")," -> VARCHAR(45), | N12: ="COMMENT ON COLUMN "&$H$3&"."&$K12&" IS '"&C12&"';" -> COMMENT ON COLUMN bfs_service_summary_device.product_code IS '商品コード'; | R12: product_code VARCHAR(45),
B13: 7 | C13: メーカ | D13: VARCHAR | E13: 1800 | F13: － | K13: manufacturer | L13: =D13&"("&E13&")," -> VARCHAR(1800), | N13: ="COMMENT ON COLUMN "&$H$3&"."&$K13&" IS '"&C13&"';" -> COMMENT ON COLUMN bfs_service_summary_device.manufacturer IS 'メーカ'; | R13: manufacturer VARCHAR(1800),
B14: 8 | C14: 移動機分類 | D14: VARCHAR | E14: 900 | F14: － | K14: mobile_device_classification | L14: =D14&"("&E14&")," -> VARCHAR(900), | N14: ="COMMENT ON COLUMN "&$H$3&"."&$K14&" IS '"&C14&"';" -> COMMENT ON COLUMN bfs_service_summary_device.mobile_device_classification IS '移動機分類'; | R14: mobile_device_classification VARCHAR(900),
B15: 9 | C15: 機種名 | D15: VARCHAR | E15: 900 | F15: － | K15: model_name | L15: =D15&"("&E15&")," -> VARCHAR(900), | N15: ="COMMENT ON COLUMN "&$H$3&"."&$K15&" IS '"&C15&"';" -> COMMENT ON COLUMN bfs_service_summary_device.model_name IS '機種名'; | R15: model_name VARCHAR(900),
B16: 10 | C16: カラー1 | D16: VARCHAR | E16: 900 | F16: － | K16: color_1 | L16: =D16&"("&E16&")," -> VARCHAR(900), | N16: ="COMMENT ON COLUMN "&$H$3&"."&$K16&" IS '"&C16&"';" -> COMMENT ON COLUMN bfs_service_summary_device.color_1 IS 'カラー1'; | R16: color_1 VARCHAR(900),
B17: 11 | C17: 台数1 | D17: DECIMAL | E17: 10 | F17: － | K17: quantity_1 | L17: =D17&"("&E17&")," -> DECIMAL(10), | N17: ="COMMENT ON COLUMN "&$H$3&"."&$K17&" IS '"&C17&"';" -> COMMENT ON COLUMN bfs_service_summary_device.quantity_1 IS '台数1'; | R17: quantity_1 DECIMAL(10),
B18: 12 | C18: カラー2 | D18: VARCHAR | E18: 900 | F18: － | K18: color_2 | L18: =D18&"("&E18&")," -> VARCHAR(900), | N18: ="COMMENT ON COLUMN "&$H$3&"."&$K18&" IS '"&C18&"';" -> COMMENT ON COLUMN bfs_service_summary_device.color_2 IS 'カラー2'; | R18: color_2 VARCHAR(900),
... B508: 502 | C508: esim登録 | D508: VARCHAR | E508: 2295 | F508: － | K508: esim_registration | L508: =D508&"("&E508&")," -> VARCHAR(2295), | N508: ="COMMENT ON COLUMN "&$H$3&"."&$K508&" IS '"&C508&"';" -> COMMENT ON COLUMN bfs_service_summary_device.esim_registration IS 'esim登録'; | R508: esim_registration VARCHAR(2295),
B509: 503 | C509: 現端末契約期間 | D509: DECIMAL | E509: 2,0 | F509: － | K509: current_device_contract_period | L509: =D509&"("&E509&")," -> DECIMAL(2,0), | N509: ="COMMENT ON COLUMN "&$H$3&"."&$K509&" IS '"&C509&"';" -> COMMENT ON COLUMN bfs_service_summary_device.current_device_contract_period IS '現端末契約期間'; | R509: current_device_contract_period DECIMAL(2,0),
B510: 504 | C510: サマリ単位反映 | D510: VARCHAR | E510: 90 | F510: － | K510: reflected_in_summary_unit | L510: =D510&"("&E510&")," -> VARCHAR(90), | N510: ="COMMENT ON COLUMN "&$H$3&"."&$K510&" IS '"&C510&"';" -> COMMENT ON COLUMN bfs_service_summary_device.reflected_in_summary_unit IS 'サマリ単位反映'; | R510: reflected_in_summary_unit VARCHAR(90),
K511: ="CONSTRAINT pk_"&H3&" PRIMARY KEY (id));" -> CONSTRAINT pk_bfs_service_summary_device PRIMARY KEY (id)); | R511: CONSTRAINT pk_bfs_service_summary_device PRIMARY KEY (id));
R512: COMMENT ON TABLE bfs_service_summary_device IS 'b_hjn_bfs_モバイル_サービスサマリ_端末';
R513: COMMENT ON COLUMN bfs_service_summary_device.id IS 'id';
R514: COMMENT ON COLUMN bfs_service_summary_device.entry_number IS 'エントリ番号';
R515: COMMENT ON COLUMN bfs_service_summary_device.summary_number IS 'サマリ番号';
R516: COMMENT ON COLUMN bfs_service_summary_device.number_of_lines IS '回線数';
R517: COMMENT ON COLUMN bfs_service_summary_device.rental_set_device IS 'レンタルセット端末';
R518: COMMENT ON COLUMN bfs_service_summary_device.mnp IS 'mnp';
R519: COMMENT ON COLUMN bfs_service_summary_device.product_code IS '商品コード';
R520: COMMENT ON COLUMN bfs_service_summary_device.manufacturer IS 'メーカ';
R521: COMMENT ON COLUMN bfs_service_summary_device.mobile_device_classification IS '移動機分類';
R522: COMMENT ON COLUMN bfs_service_summary_device.model_name IS '機種名';
R523: COMMENT ON COLUMN bfs_service_summary_device.color_1 IS 'カラー1';
... R1017: COMMENT ON COLUMN bfs_service_summary_device.reflected_in_summary_unit IS 'サマリ単位反映';

Sheet (BFSエントリ)モバイル_エントリ情報
C2: 種別 | D2: DWH公開名 | E2: 旧DWH公開名 | F2: 統合テーブルID | G2: スキーマ
C3: ビュー | D3: b_hjn_bfs_モバイル_エントリ情報 | F3: V004409 | G3: user_l2_prvl | H3: user_l2_prvl | K3: bfs_entry_information
C4: データ概要：
C5: （BFS）モバイル_エントリ情報
K6: ="DROP TABLE IF EXISTS "&K3&" CASCADE;" -> DROP TABLE IF EXISTS bfs_entry_information CASCADE; | R6: DROP TABLE IF EXISTS bfs_entry_information CASCADE;
K7: ="CREATE TABLE IF NOT EXISTS "&K3&" (" -> CREATE TABLE IF NOT EXISTS bfs_entry_information ( | N7: ="COMMENT ON TABLE "&K3&" IS '"&D3&"';" -> COMMENT ON TABLE bfs_entry_information IS 'b_hjn_bfs_モバイル_エントリ情報'; | R7: CREATE TABLE IF NOT EXISTS bfs_entry_information (
A8: pk | B8: SEQ | C8: 項目名 | D8: TYPE | E8: 桁 | F8: 仮名化 | G8: 項目説明およびリスト値 | H8: コードリファレンスリンク | I8: 備考 | J8: 更新日 | K8: id BIGINT GENERATED BY DEFAULT AS IDENTITY, | N8: ="COMMENT ON COLUMN "&$K$3&".id IS 'id';" -> COMMENT ON COLUMN bfs_entry_information.id IS 'id'; | R8: id BIGINT GENERATED BY DEFAULT AS IDENTITY,
B9: 1 | C9: エントリ番号 | D9: VARCHAR | E9: 54 | F9: － | K9: entry_number | L9: =D9&"("&E9&")," -> VARCHAR(54), | N9: ="COMMENT ON COLUMN "&$K$3&"."&$K9&" IS '"&C9&"';" -> COMMENT ON COLUMN bfs_entry_information.entry_number IS 'エントリ番号'; | R9: entry_number VARCHAR(54),
B10: 2 | C10: 件名 | D10: VARCHAR | E10: 2304 | F10: － | K10: subject | L10: =D10&"("&E10&")," -> VARCHAR(2304), | N10: ="COMMENT ON COLUMN "&$K$3&"."&$K10&" IS '"&C10&"';" -> COMMENT ON COLUMN bfs_entry_information.subject IS '件名'; | R10: subject VARCHAR(2304),
B11: 3 | C11: 作成区分 | D11: VARCHAR | E11: 900 | F11: － | K11: creation_category | L11: =D11&"("&E11&")," -> VARCHAR(900), | N11: ="COMMENT ON COLUMN "&$K$3&"."&$K11&" IS '"&C11&"';" -> COMMENT ON COLUMN bfs_entry_information.creation_category IS '作成区分'; | R11: creation_category VARCHAR(900),
B12: 4 | C12: オーダ種別 | D12: VARCHAR | E12: 900 | F12: － | K12: order_type | L12: =D12&"("&E12&")," -> VARCHAR(900), | N12: ="COMMENT ON COLUMN "&$K$3&"."&$K12&" IS '"&C12&"';" -> COMMENT ON COLUMN bfs_entry_information.order_type IS 'オーダ種別'; | R12: order_type VARCHAR(900),
B13: 5 | C13: 申込書連携 | D13: VARCHAR | E13: 900 | F13: － | K13: application_form_linkage | L13: =D13&"("&E13&")," -> VARCHAR(900), | N13: ="COMMENT ON COLUMN "&$K$3&"."&$K13&" IS '"&C13&"';" -> COMMENT ON COLUMN bfs_entry_information.application_form_linkage IS '申込書連携'; | R13: application_form_linkage VARCHAR(900),
B14: 6 | C14: 特約分離出力有無 | D14: VARCHAR | E14: 900 | F14: － | K14: special_contract_separate_output | L14: =D14&"("&E14&")," -> VARCHAR(900), | N14: ="COMMENT ON COLUMN "&$K$3&"."&$K14&" IS '"&C14&"';" -> COMMENT ON COLUMN bfs_entry_information.special_contract_separate_output IS '特約分離出力有無'; | R14: special_contract_separate_output VARCHAR(900),
B15: 7 | C15: 通知書対象 | D15: VARCHAR | E15: 900 | F15: － | K15: notification_target | L15: =D15&"("&E15&")," -> VARCHAR(900), | N15: ="COMMENT ON COLUMN "&$K$3&"."&$K15&" IS '"&C15&"';" -> COMMENT ON COLUMN bfs_entry_information.notification_target IS '通知書対象'; | R15: notification_target VARCHAR(900),
B16: 8 | C16: 開通済有無 | D16: VARCHAR | E16: 900 | F16: － | K16: activation_status | L16: =D16&"("&E16&")," -> VARCHAR(900), | N16: ="COMMENT ON COLUMN "&$K$3&"."&$K16&" IS '"&C16&"';" -> COMMENT ON COLUMN bfs_entry_information.activation_status IS '開通済有無'; | R16: activation_status VARCHAR(900),
B17: 9 | C17: 開通日 | D17: VARCHAR | E17: 60 | F17: － | K17: activation_date | L17: =D17&"("&E17&")," -> VARCHAR(60), | N17: ="COMMENT ON COLUMN "&$K$3&"."&$K17&" IS '"&C17&"';" -> COMMENT ON COLUMN bfs_entry_information.activation_date IS '開通日'; | R17: activation_date VARCHAR(60),
B18: 10 | C18: 非完結依頼種別 | D18: VARCHAR | E18: 900 | F18: － | K18: incomplete_request_type | L18: =D18&"("&E18&")," -> VARCHAR(900), | N18: ="COMMENT ON COLUMN "&$K$3&"."&$K18&" IS '"&C18&"';" -> COMMENT ON COLUMN bfs_entry_information.incomplete_request_type IS '非完結依頼種別'; | R18: incomplete_request_type VARCHAR(900),
B19: 11 | C19: コピー元エントリ種別 | D19: VARCHAR | E19: 900 | F19: － | K19: source_entry_type | L19: =D19&"("&E19&")," -> VARCHAR(900), | N19: ="COMMENT ON COLUMN "&$K$3&"."&$K19&" IS '"&C19&"';" -> COMMENT ON COLUMN bfs_entry_information.source_entry_type IS 'コピー元エントリ種別'; | R19: source_entry_type VARCHAR(900),
B20: 12 | C20: 営業担当者コード | D20: VARCHAR | E20: 21 | F20: － | K20: salesperson_code | L20: =D20&"("&E20&")," -> VARCHAR(21), | N20: ="COMMENT ON COLUMN "&$K$3&"."&$K20&" IS '"&C20&"';" -> COMMENT ON COLUMN bfs_entry_information.salesperson_code IS '営業担当者コード'; | R20: salesperson_code VARCHAR(21),
... B224: 216 | C224: rental_中古_期間_ヶ月 | D224: VARCHAR | E224: 6 | F224: － | K224: rental_used_period_months | L224: =D224&"("&E224&")," -> VARCHAR(6), | N224: ="COMMENT ON COLUMN "&$K$3&"."&$K224&" IS '"&C224&"';" -> COMMENT ON COLUMN bfs_entry_information.rental_used_period_months IS 'rental_中古_期間_ヶ月'; | R224: rental_used_period_months VARCHAR(6),
K225: ="CONSTRAINT pk_"&K3&" PRIMARY KEY (id));" -> CONSTRAINT pk_bfs_entry_information PRIMARY KEY (id)); | R225: CONSTRAINT pk_bfs_entry_information PRIMARY KEY (id));
R226: COMMENT ON TABLE bfs_entry_information IS 'b_hjn_bfs_モバイル_エントリ情報';
R227: COMMENT ON COLUMN bfs_entry_information.id IS 'id';
R228: COMMENT ON COLUMN bfs_entry_information.entry_number IS 'エントリ番号';
R229: COMMENT ON COLUMN bfs_entry_information.subject IS '件名';
R230: COMMENT ON COLUMN bfs_entry_information.creation_category IS '作成区分';
R231: COMMENT ON COLUMN bfs_entry_information.order_type IS 'オーダ種別';
R232: COMMENT ON COLUMN bfs_entry_information.application_form_linkage IS '申込書連携';
R233: COMMENT ON COLUMN bfs_entry_information.special_contract_separate_output IS '特約分離出力有無';
R234: COMMENT ON COLUMN bfs_entry_information.notification_target IS '通知書対象';
R235: COMMENT ON COLUMN bfs_entry_information.activation_status IS '開通済有無';
R236: COMMENT ON COLUMN bfs_entry_information.activation_date IS '開通日';
R237: COMMENT ON COLUMN bfs_entry_information.incomplete_request_type IS '非完結依頼種別';
... R443: COMMENT ON COLUMN bfs_entry_information.rental_used_period_months IS 'rental_中古_期間_ヶ月';

Sheet (RMS)契約基本情報
F2: 種別 | G2: DWH公開名 | H2: 旧DWH公開名 | I2: 統合テーブルID | J2: スキーマ
F3: ビュー | G3: b_hjn_rms_契約基本情報 | I3: V004566 | J3: user_l2_prvl | K3: rms_contract_basic_information
F4: データ概要：
F5: オーダー番号毎に、納品先、契約内容、支払い方法等の情報を持つ
K6: ="DROP TABLE IF EXISTS "&K3&" CASCADE;" -> DROP TABLE IF EXISTS rms_contract_basic_information CASCADE; | R6: DROP TABLE IF EXISTS rms_contract_basic_information CASCADE;
K7: ="CREATE TABLE IF NOT EXISTS "&K3&" (" -> CREATE TABLE IF NOT EXISTS rms_contract_basic_information ( | N7: ="COMMENT ON TABLE "&K3&" IS '"&G3&"';" -> COMMENT ON TABLE rms_contract_basic_information IS 'b_hjn_rms_契約基本情報'; | R7: CREATE TABLE IF NOT EXISTS rms_contract_basic_information (
A8: pk | B8: SEQ | C8: 項目名 | D8: TYPE | E8: 桁 | F8: 仮名化 | G8: 項目説明およびリスト値 | H8: コードリファレンスリンク | I8: 備考 | J8: 更新日 | K8: id BIGINT GENERATED BY DEFAULT AS IDENTITY, | N8: ="COMMENT ON COLUMN "&$K$3&".id IS 'id';" -> COMMENT ON COLUMN rms_contract_basic_information.id IS 'id'; | R8: id BIGINT GENERATED BY DEFAULT AS IDENTITY,
B9: 1 | C9: オーダ番号 | D9: VARCHAR | E9: 48 | F9: － | K9: order_number | L9: =D9&"("&E9&")," -> VARCHAR(48), | N9: ="COMMENT ON COLUMN "&$K$3&"."&$K9&" IS '"&C9&"';" -> COMMENT ON COLUMN rms_contract_basic_information.order_number IS 'オーダ番号'; | R9: order_number VARCHAR(48),
B10: 2 | C10: オーダ明細行番号 | D10: VARCHAR | E10: 9 | F10: － | G10: 1～999で指定可能 | K10: order_detail_line_number | L10: =D10&"("&E10&")," -> VARCHAR(9), | N10: ="COMMENT ON COLUMN "&$K$3&"."&$K10&" IS '"&C10&"';" -> COMMENT ON COLUMN rms_contract_basic_information.order_detail_line_number IS 'オーダ明細行番号'; | R10: order_detail_line_number VARCHAR(9),
B11: 3 | C11: g3オーダ番号 | D11: VARCHAR | E11: 48 | F11: － | G11: UK | K11: g3_order_number | L11: =D11&"("&E11&")," -> VARCHAR(48), | N11: ="COMMENT ON COLUMN "&$K$3&"."&$K11&" IS '"&C11&"';" -> COMMENT ON COLUMN rms_contract_basic_information.g3_order_number IS 'g3オーダ番号'; | R11: g3_order_number VARCHAR(48),
B12: 4 | C12: g3オーダ回線コード | D12: VARCHAR | E12: 48 | F12: － | G12: UK。 G3のグリッド画面の行番号に相当 | K12: g3_order_line_code | L12: =D12&"("&E12&")," -> VARCHAR(48), | N12: ="COMMENT ON COLUMN "&$K$3&"."&$K12&" IS '"&C12&"';" -> COMMENT ON COLUMN rms_contract_basic_information.g3_order_line_code IS 'g3オーダ回線コード'; | R12: g3_order_line_code VARCHAR(48),
B13: 5 | C13: s# | D13: VARCHAR | E13: 30 | F13: － | K13: ssharp | L13: =D13&"("&E13&")," -> VARCHAR(30), | N13: ="COMMENT ON COLUMN "&$K$3&"."&$K13&" IS '"&C13&"';" -> COMMENT ON COLUMN rms_contract_basic_information.ssharp IS 's#'; | R13: ssharp VARCHAR(30),
B14: 6 | C14: b# | D14: VARCHAR | E14: 30 | F14: － | G14: 洗替処理にてB#を更新 | K14: bsharp | L14: =D14&"("&E14&")," -> VARCHAR(30), | N14: ="COMMENT ON COLUMN "&$K$3&"."&$K14&" IS '"&C14&"';" -> COMMENT ON COLUMN rms_contract_basic_information.bsharp IS 'b#'; | R14: bsharp VARCHAR(30),
B15: 7 | C15: 機種契約s# | D15: VARCHAR | E15: 30 | F15: － | G15: ハイフンの場合 回線契約のみ nullの場合 新規、MNP等、開通前(COPから機種情報が払い出される前) | K15: model_contract_ssharp | L15: =D15&"("&E15&")," -> VARCHAR(30), | N15: ="COMMENT ON COLUMN "&$K$3&"."&$K15&" IS '"&C15&"';" -> COMMENT ON COLUMN rms_contract_basic_information.model_contract_ssharp IS '機種契約s#'; | R15: model_contract_ssharp VARCHAR(30),
B16: 8 | C16: 機種契約b# | D16: VARCHAR | E16: 30 | F16: － | G16: ハイフンの場合 回線契約のみ nullの場合 新規、MNP等、開通前(COPから機種情報が払い出される前) | K16: model_contract_bsharp | L16: =D16&"("&E16&")," -> VARCHAR(30), | N16: ="COMMENT ON COLUMN "&$K$3&"."&$K16&" IS '"&C16&"';" -> COMMENT ON COLUMN rms_contract_basic_information.model_contract_bsharp IS '機種契約b#'; | R16: model_contract_bsharp VARCHAR(30),
B17: 9 | C17: 群番号 | D17: VARCHAR | E17: 6 | F17: － | G17: 毎回、BC洗替によりセット。 10：10群 20：20群 30：30群 70：70群 80：業務用 90：VPNグループ用 | K17: group_number | L17: =D17&"("&E17&")," -> VARCHAR(6), | N17: ="COMMENT ON COLUMN "&$K$3&"."&$K17&" IS '"&C17&"';" -> COMMENT ON COLUMN rms_contract_basic_information.group_number IS '群番号'; | R17: group_number VARCHAR(6),
B18: 10 | C18: カタログ品目コード | D18: VARCHAR | E18: 45 | F18: － | G18: コード変換はカタログ品目マスタ参照 | K18: catalog_item_code | L18: =D18&"("&E18&")," -> VARCHAR(45), | N18: ="COMMENT ON COLUMN "&$K$3&"."&$K18&" IS '"&C18&"';" -> COMMENT ON COLUMN rms_contract_basic_information.catalog_item_code IS 'カタログ品目コード'; | R18: catalog_item_code VARCHAR(45),
B19: 11 | C19: カタログ品目コード名 | D19: VARCHAR | E19: 450 | F19: － | G19: カタログ品目マスタ[品目略称] | K19: catalog_item_code_name | L19: =D19&"("&E19&")," -> VARCHAR(450), | N19: ="COMMENT ON COLUMN "&$K$3&"."&$K19&" IS '"&C19&"';" -> COMMENT ON COLUMN rms_contract_basic_information.catalog_item_code_name IS 'カタログ品目コード名'; | R19: catalog_item_code_name VARCHAR(450),
B20: 12 | C20: 変換後カタログ品目cd | D20: VARCHAR | E20: 45 | F20: － | G20: コード変換はカタログ品目マスタ参照 | K20: converted_catalog_item_cd | L20: =D20&"("&E20&")," -> VARCHAR(45), | N20: ="COMMENT ON COLUMN "&$K$3&"."&$K20&" IS '"&C20&"';" -> COMMENT ON COLUMN rms_contract_basic_information.converted_catalog_item_cd IS '変換後カタログ品目cd'; | R20: converted_catalog_item_cd VARCHAR(45),
B21: 13 | C21: 変換後catalogs品目cd名 | D21: VARCHAR | E21: 450 | F21: － | G21: カタログ品目マスタ[品目略称] | K21: converted_catalog_item_cd_name | L21: =D21&"("&E21&")," -> VARCHAR(450), | N21: ="COMMENT ON COLUMN "&$K$3&"."&$K21&" IS '"&C21&"';" -> COMMENT ON COLUMN rms_contract_basic_information.converted_catalog_item_cd_name IS '変換後catalogs品目cd名'; | R21: converted_catalog_item_cd_name VARCHAR(450),
B22: 14 | C22: 色 | D22: VARCHAR | E22: 1800 | F22: － | G22: UTF全角。 画面では利用しない。 | K22: color | L22: =D22&"("&E22&")," -> VARCHAR(1800), | N22: ="COMMENT ON COLUMN "&$K$3&"."&$K22&" IS '"&C22&"';" -> COMMENT ON COLUMN rms_contract_basic_information.color IS '色'; | R22: color VARCHAR(1800),
B23: 15 | C23: 旧移動機販売方法 | D23: VARCHAR | E23: 6 | F23: － | G23: 0：請求書支払い 1：通話料同時請求 2：無償 3：割賦 4：通常 5：代引き 6：レンタル | K23: old_mobile_device_sales_method | L23: =D23&"("&E23&")," -> VARCHAR(6), | N23: ="COMMENT ON COLUMN "&$K$3&"."&$K23&" IS '"&C23&"';" -> COMMENT ON COLUMN rms_contract_basic_information.old_mobile_device_sales_method IS '旧移動機販売方法'; | R23: old_mobile_device_sales_method VARCHAR(6),
B24: 16 | C24: 納品先社名 | D24: VARCHAR | E24: 2295 | F24: － | G24: UTF全角 | K24: delivery_company_name | L24: =D24&"("&E24&")," -> VARCHAR(2295), | N24: ="COMMENT ON COLUMN "&$K$3&"."&$K24&" IS '"&C24&"';" -> COMMENT ON COLUMN rms_contract_basic_information.delivery_company_name IS '納品先社名'; | R24: delivery_company_name VARCHAR(2295),
B25: 17 | C25: 納品先部署名 | D25: VARCHAR | E25: 270 | F25: － | G25: UTF全角 | K25: delivery_department_name | L25: =D25&"("&E25&")," -> VARCHAR(270), | N25: ="COMMENT ON COLUMN "&$K$3&"."&$K25&" IS '"&C25&"';" -> COMMENT ON COLUMN rms_contract_basic_information.delivery_department_name IS '納品先部署名'; | R25: delivery_department_name VARCHAR(270),
... B27: 19 | C27: 納品先ご担当者名カナ | D27: VARCHAR | E27: 540 | F27: － | G27: UTF全角 | K27: delivery_contact_name_kana | L27: =D27&"("&E27&")," -> VARCHAR(540), | N27: ="COMMENT ON COLUMN "&$K$3&"."&$K27&" IS '"&C27&"';" -> COMMENT ON COLUMN rms_contract_basic_information.delivery_contact_name_kana IS '納品先ご担当者名カナ'; | R27: delivery_contact_name_kana VARCHAR(540),
B28: 20 | C28: 納品先郵便番号 | D28: VARCHAR | E28: 21 | F28: － | K28: delivery_postal_code | L28: =D28&"("&E28&")," -> VARCHAR(21), | N28: ="COMMENT ON COLUMN "&$K$3&"."&$K28&" IS '"&C28&"';" -> COMMENT ON COLUMN rms_contract_basic_information.delivery_postal_code IS '納品先郵便番号'; | R28: delivery_postal_code VARCHAR(21),
B29: 21 | C29: 納品先都道府県 | D29: VARCHAR | E29: 90 | F29: － | G29: UTF全角 | K29: delivery_prefecture | L29: =D29&"("&E29&")," -> VARCHAR(90), | N29: ="COMMENT ON COLUMN "&$K$3&"."&$K29&" IS '"&C29&"';" -> COMMENT ON COLUMN rms_contract_basic_information.delivery_prefecture IS '納品先都道府県'; | R29: delivery_prefecture VARCHAR(90),
B30: 22 | C30: 納品先市区郡町村 | D30: VARCHAR | E30: 720 | F30: － | G30: UTF全角 | K30: delivery_address_city | L30: =D30&"("&E30&")," -> VARCHAR(720), | N30: ="COMMENT ON COLUMN "&$K$3&"."&$K30&" IS '"&C30&"';" -> COMMENT ON COLUMN rms_contract_basic_information.delivery_address_city IS '納品先市区郡町村'; | R30: delivery_address_city VARCHAR(720),
B31: 23 | C31: 納品先通称大字 | D31: VARCHAR | E31: 720 | F31: － | G31: UTF全角 | K31: delivery_address_oaza | L31: =D31&"("&E31&")," -> VARCHAR(720), | N31: ="COMMENT ON COLUMN "&$K$3&"."&$K31&" IS '"&C31&"';" -> COMMENT ON COLUMN rms_contract_basic_information.delivery_address_oaza IS '納品先通称大字'; | R31: delivery_address_oaza VARCHAR(720),
B32: 24 | C32: 納品先丁目字等 | D32: VARCHAR | E32: 720 | F32: － | G32: UTF全角 | K32: delivery_address_block | L32: =D32&"("&E32&")," -> VARCHAR(720), | N32: ="COMMENT ON COLUMN "&$K$3&"."&$K32&" IS '"&C32&"';" -> COMMENT ON COLUMN rms_contract_basic_information.delivery_address_block IS '納品先丁目字等'; | R32: delivery_address_block VARCHAR(720),
B33: 25 | C33: 納品先番地 | D33: VARCHAR | E33: 720 | F33: － | G33: UTF全角 | K33: delivery_address_street | L33: =D33&"("&E33&")," -> VARCHAR(720), | N33: ="COMMENT ON COLUMN "&$K$3&"."&$K33&" IS '"&C33&"';" -> COMMENT ON COLUMN rms_contract_basic_information.delivery_address_street IS '納品先番地'; | R33: delivery_address_street VARCHAR(720),
B34: 26 | C34: 納品先_部屋no | D34: VARCHAR | E34: 2295 | F34: － | G34: UTF全角 | K34: delivery_room_no | L34: =D34&"("&E34&")," -> VARCHAR(2295), | N34: ="COMMENT ON COLUMN "&$K$3&"."&$K34&" IS '"&C34&"';" -> COMMENT ON COLUMN rms_contract_basic_information.delivery_room_no IS '納品先_部屋no'; | R34: delivery_room_no VARCHAR(2295),
B35: 27 | C35: 納品先電話番号 | D35: VARCHAR | E35: 117 | F35: － | G35: UTF全角 | K35: delivery_phone_number | L35: =D35&"("&E35&")," -> VARCHAR(117), | N35: ="COMMENT ON COLUMN "&$K$3&"."&$K35&" IS '"&C35&"';" -> COMMENT ON COLUMN rms_contract_basic_information.delivery_phone_number IS '納品先電話番号'; | R35: delivery_phone_number VARCHAR(117),
B36: 28 | C36: 回線契約ステータス | D36: VARCHAR | E36: 6 | F36: － | G36: コード変換はコードマスタ「大区分コード：106」参照 | K36: line_contract_status | L36: =D36&"("&E36&")," -> VARCHAR(6), | N36: ="COMMENT ON COLUMN "&$K$3&"."&$K36&" IS '"&C36&"';" -> COMMENT ON COLUMN rms_contract_basic_information.line_contract_status IS '回線契約ステータス'; | R36: line_contract_status VARCHAR(6),
B37: 29 | C37: 回線契約ステータス名 | D37: VARCHAR | E37: 300 | F37: － | G37: コードマスタの[内容] 「大区分コード：106」 | K37: line_contract_status_name | L37: =D37&"("&E37&")," -> VARCHAR(300), | N37: ="COMMENT ON COLUMN "&$K$3&"."&$K37&" IS '"&C37&"';" -> COMMENT ON COLUMN rms_contract_basic_information.line_contract_status_name IS '回線契約ステータス名'; | R37: line_contract_status_name VARCHAR(300),
B38: 30 | C38: 利用期間 | D38: DECIMAL | E38: 9 | F38: － | G38: 単位：ヶ月 | K38: usage_period | L38: =D38&"("&E38&")," -> DECIMAL(9), | N38: ="COMMENT ON COLUMN "&$K$3&"."&$K38&" IS '"&C38&"';" -> COMMENT ON COLUMN rms_contract_basic_information.usage_period IS '利用期間'; | R38: usage_period DECIMAL(9),
B39: 31 | C39: 充当ポイント | D39: DECIMAL | E39: 30 | F39: － | G39: レンタル登録事務手数料に対する充当ポイント。 ※オーダ確定時の情報 | K39: allocation_points | L39: =D39&"("&E39&")," -> DECIMAL(30), | N39: ="COMMENT ON COLUMN "&$K$3&"."&$K39&" IS '"&C39&"';" -> COMMENT ON COLUMN rms_contract_basic_information.allocation_points IS '充当ポイント'; | R39: allocation_points DECIMAL(30),
B40: 32 | C40: 契約ステータス | D40: VARCHAR | E40: 6 | F40: － | G40: コード変換はコードマスタ「大区分コード：107」参照 | K40: contract_status | L40: =D40&"("&E40&")," -> VARCHAR(6), | N40: ="COMMENT ON COLUMN "&$K$3&"."&$K40&" IS '"&C40&"';" -> COMMENT ON COLUMN rms_contract_basic_information.contract_status IS '契約ステータス'; | R40: contract_status VARCHAR(6),
... B67: 59 | C67: 更新ユーザ | D67: VARCHAR | E67: 96 | F67: － | G67: 初回登録時及び更新時に担当者コード又はプログラムIDをセット。 | K67: updated_user | L67: =D67&"("&E67&")," -> VARCHAR(96), | N67: ="COMMENT ON COLUMN "&$K$3&"."&$K67&" IS '"&C67&"';" -> COMMENT ON COLUMN rms_contract_basic_information.updated_user IS '更新ユーザ'; | R67: updated_user VARCHAR(96),
B68: 60 | C68: summit統一企業番号 | D68: VARCHAR | E68: 48 | F68: － | K68: summit_unified_company_number | L68: =D68&"("&E68&")," -> VARCHAR(48), | N68: ="COMMENT ON COLUMN "&$K$3&"."&$K68&" IS '"&C68&"';" -> COMMENT ON COLUMN rms_contract_basic_information.summit_unified_company_number IS 'summit統一企業番号'; | R68: summit_unified_company_number VARCHAR(48),
...

Sheet (RMS)契約料金情報
F2: 種別 | G2: DWH公開名 | H2: 旧DWH公開名 | I2: 統合テーブルID | J2: スキーマ
F3: ビュー | G3: b_hjn_rms_契約料金情報 | I3: V004573 | J3: user_l2_prvl | K3: rms_contract_fee_information
F4: データ概要：
F5: オーダー番号毎に、契約料金情報等の情報を持つ
K6: ="DROP TABLE IF EXISTS "&K3&" CASCADE;" -> DROP TABLE IF EXISTS rms_contract_fee_information CASCADE; | R6: DROP TABLE IF EXISTS rms_contract_fee_information CASCADE;
K7: ="CREATE TABLE IF NOT EXISTS "&K3&" (" -> CREATE TABLE IF NOT EXISTS rms_contract_fee_information ( | N7: ="COMMENT ON TABLE "&K3&" IS '"&G3&"';" -> COMMENT ON TABLE rms_contract_fee_information IS 'b_hjn_rms_契約料金情報'; | R7: CREATE TABLE IF NOT EXISTS rms_contract_fee_information (
A8: pk | B8: SEQ | C8: 項目名 | D8: TYPE | E8: 桁 | F8: 仮名化 | G8: 項目説明およびリスト値 | H8: コードリファレンスリンク | I8: 備考 | J8: 更新日 | K8: id BIGINT GENERATED BY DEFAULT AS IDENTITY, | N8: ="COMMENT ON COLUMN "&$K$3&".id IS 'id';" -> COMMENT ON COLUMN rms_contract_fee_information.id IS 'id'; | R8: id BIGINT GENERATED BY DEFAULT AS IDENTITY,
B9: 1 | C9: オーダ番号 | D9: VARCHAR | E9: 48 | F9: － | K9: order_number | L9: =D9&"("&E9&")," -> VARCHAR(48), | N9: ="COMMENT ON COLUMN "&$K$3&"."&$K9&" IS '"&C9&"';" -> COMMENT ON COLUMN rms_contract_fee_information.order_number IS 'オーダ番号'; | R9: order_number VARCHAR(48),
B10: 2 | C10: オーダ明細行番号 | D10: VARCHAR | E10: 9 | F10: － | K10: order_detail_line_number | L10: =D10&"("&E10&")," -> VARCHAR(9), | N10: ="COMMENT ON COLUMN "&$K$3&"."&$K10&" IS '"&C10&"';" -> COMMENT ON COLUMN rms_contract_fee_information.order_detail_line_number IS 'オーダ明細行番号'; | R10: order_detail_line_number VARCHAR(9),
B11: 3 | C11: オーダ料金明細行番号 | D11: VARCHAR | E11: 9 | F11: － | K11: order_charge_detail_line_number | L11: =D11&"("&E11&")," -> VARCHAR(9), | N11: ="COMMENT ON COLUMN "&$K$3&"."&$K11&" IS '"&C11&"';" -> COMMENT ON COLUMN rms_contract_fee_information.order_charge_detail_line_number IS 'オーダ料金明細行番号'; | R11: order_charge_detail_line_number VARCHAR(9),
B12: 4 | C12: 料金項目id | D12: VARCHAR | E12: 18 | F12: － | K12: charge_item_id | L12: =D12&"("&E12&")," -> VARCHAR(18), | N12: ="COMMENT ON COLUMN "&$K$3&"."&$K12&" IS '"&C12&"';" -> COMMENT ON COLUMN rms_contract_fee_information.charge_item_id IS '料金項目id'; | R12: charge_item_id VARCHAR(18),
B13: 5 | C13: 料金項目名称 | D13: VARCHAR | E13: 600 | F13: － | G13: UTF全角。 画面表示用の料金項目名 | K13: charge_item_name | L13: =D13&"("&E13&")," -> VARCHAR(600), | N13: ="COMMENT ON COLUMN "&$K$3&"."&$K13&" IS '"&C13&"';" -> COMMENT ON COLUMN rms_contract_fee_information.charge_item_name IS '料金項目名称'; | R13: charge_item_name VARCHAR(600),
B14: 6 | C14: 料金項目分類コード | D14: VARCHAR | E14: 9 | F14: － | G14: コード変換はコードマスタ「大区分コード：406」参照 | K14: charge_item_classification_code | L14: =D14&"("&E14&")," -> VARCHAR(9), | N14: ="COMMENT ON COLUMN "&$K$3&"."&$K14&" IS '"&C14&"';" -> COMMENT ON COLUMN rms_contract_fee_information.charge_item_classification_code IS '料金項目分類コード'; | R14: charge_item_classification_code VARCHAR(9),
B15: 7 | C15: 料金項目分類コード名 | D15: VARCHAR | E15: 300 | F15: － | G15: コードマスタの[内容] 「大区分コード：406」 | K15: charge_item_classification_code_name | L15: =D15&"("&E15&")," -> VARCHAR(300), | N15: ="COMMENT ON COLUMN "&$K$3&"."&$K15&" IS '"&C15&"';" -> COMMENT ON COLUMN rms_contract_fee_information.charge_item_classification_code_name IS '料金項目分類コード名'; | R15: charge_item_classification_code_name VARCHAR(300),
B16: 8 | C16: 表示ソート制御 | D16: DECIMAL | E16: 12 | F16: － | G16: 料金マスタのソート情報を保持 | K16: display_sort_control | L16: =D16&"("&E16&")," -> DECIMAL(12), | N16: ="COMMENT ON COLUMN "&$K$3&"."&$K16&" IS '"&C16&"';" -> COMMENT ON COLUMN rms_contract_fee_information.display_sort_control IS '表示ソート制御'; | R16: display_sort_control DECIMAL(12),
B17: 9 | C17: 契約開始日 | D17: VARCHAR | E17: 24 | F17: － | G17: YYYYMMDD形式 | K17: contract_start_date | L17: =D17&"("&E17&")," -> VARCHAR(24), | N17: ="COMMENT ON COLUMN "&$K$3&"."&$K17&" IS '"&C17&"';" -> COMMENT ON COLUMN rms_contract_fee_information.contract_start_date IS '契約開始日'; | R17: contract_start_date VARCHAR(24),
B18: 10 | C18: 契約終了日 | D18: VARCHAR | E18: 24 | F18: － | G18: YYYYMMDD形式 | K18: contract_end_date | L18: =D18&"("&E18&")," -> VARCHAR(24), | N18: ="COMMENT ON COLUMN "&$K$3&"."&$K18&" IS '"&C18&"';" -> COMMENT ON COLUMN rms_contract_fee_information.contract_end_date IS '契約終了日'; | R18: contract_end_date VARCHAR(24),
B19: 11 | C19: 課金開始日 | D19: VARCHAR | E19: 24 | F19: － | G19: YYYYMMDD形式。 月額一時金区分が月額の場合のみ指定する。 レンタル契約情報としての課金開始日。 ※ＧＩＳＵＮからのＩＦにより自動でセットされる。（画面変更不可） | K19: billing_start_date | L19: =D19&"("&E19&")," -> VARCHAR(24), | N19: ="COMMENT ON COLUMN "&$K$3&"."&$K19&" IS '"&C19&"';" -> COMMENT ON COLUMN rms_contract_fee_information.billing_start_date IS '課金開始日'; | R19: billing_start_date VARCHAR(24),
B20: 12 | C20: 課金終了日 | D20: VARCHAR | E20: 24 | F20: － | G20: YYYYMMDD形式。 月額一時金区分が月額の場合のみ指定する。 レンタル契約情報としての課金終了日。 （解約時には、レンタル料金情報の課金終了日は更新せずに、 本項目のみを更新する）。 ※ＧＩＳＵＮからのＩＦにより自動でセットされる。（画面変更不可） | K20: billing_end_date | L20: =D20&"("&E20&")," -> VARCHAR(24), | N20: ="COMMENT ON COLUMN "&$K$3&"."&$K20&" IS '"&C20&"';" -> COMMENT ON COLUMN rms_contract_fee_information.billing_end_date IS '課金終了日'; | R20: billing_end_date VARCHAR(24),
B21: 13 | C21: 料金情報登録日 | D21: VARCHAR | E21: 24 | F21: － | G21: YYYYMMDD形式。 バッチ処理にて解約違約金をセットするタイミングで登録日をセット。 バッチ処理にて月初の請求処理前の違約金は翌月請求とする | K21: charge_information_registration_date | L21: =D21&"("&E21&")," -> VARCHAR(24), | N21: ="COMMENT ON COLUMN "&$K$3&"."&$K21&" IS '"&C21&"';" -> COMMENT ON COLUMN rms_contract_fee_information.charge_information_registration_date IS '料金情報登録日'; | R21: charge_information_registration_date VARCHAR(24),
B22: 14 | C22: 月額一時金区分 | D22: VARCHAR | E22: 3 | F22: － | G22: コード変換はコードマスタ「大区分コード：401」参照 | K22: monthly_lump_sum_category | L22: =D22&"("&E22&")," -> VARCHAR(3), | N22: ="COMMENT ON COLUMN "&$K$3&"."&$K22&" IS '"&C22&"';" -> COMMENT ON COLUMN rms_contract_fee_information.monthly_lump_sum_category IS '月額一時金区分'; | R22: monthly_lump_sum_category VARCHAR(3),
B23: 15 | C23: 月額一時金区分名 | D23: VARCHAR | E23: 300 | F23: － | G23: コードマスタの[内容] 「大区分コード：401」 | K23: monthly_lump_sum_category_name | L23: =D23&"("&E23&")," -> VARCHAR(300), | N23: ="COMMENT ON COLUMN "&$K$3&"."&$K23&" IS '"&C23&"';" -> COMMENT ON COLUMN rms_contract_fee_information.monthly_lump_sum_category_name IS '月額一時金区分名'; | R23: monthly_lump_sum_category_name VARCHAR(300),
B24: 16 | C24: 税区分 | D24: VARCHAR | E24: 3 | F24: － | G24: コード変換はコードマスタ「大区分コード：301」参照 | K24: tax_category | L24: =D24&"("&E24&")," -> VARCHAR(3), | N24: ="COMMENT ON COLUMN "&$K$3&"."&$K24&" IS '"&C24&"';" -> COMMENT ON COLUMN rms_contract_fee_information.tax_category IS '税区分'; | R24: tax_category VARCHAR(3),
... B41: 33 | C41: ポイント利用済みflg名 | D41: VARCHAR | E41: 3 | F41: － | G41: ↑の日本語名 | K41: point_used_flag_name | L41: =D41&"("&E41&")," -> VARCHAR(3), | N41: ="COMMENT ON COLUMN "&$K$3&"."&$K41&" IS '"&C41&"';" -> COMMENT ON COLUMN rms_contract_fee_information.point_used_flag_name IS 'ポイント利用済みflg名'; | R41: point_used_flag_name VARCHAR(3),
K42: ="CONSTRAINT pk_"&K3&" PRIMARY KEY (id));" -> CONSTRAINT pk_rms_contract_fee_information PRIMARY KEY (id)); | R42: CONSTRAINT pk_rms_contract_fee_information PRIMARY KEY (id));
R43: COMMENT ON TABLE rms_contract_fee_information IS 'b_hjn_rms_契約料金情報';
R44: COMMENT ON COLUMN rms_contract_fee_information.id IS 'id';
R45: COMMENT ON COLUMN rms_contract_fee_information.order_number IS 'オーダ番号';
R46: COMMENT ON COLUMN rms_contract_fee_information.order_detail_line_number IS 'オーダ明細行番号';
R47: COMMENT ON COLUMN rms_contract_fee_information.order_charge_detail_line_number IS 'オーダ料金明細行番号';
R48: COMMENT ON COLUMN rms_contract_fee_information.charge_item_id IS '料金項目id';
R49: COMMENT ON COLUMN rms_contract_fee_information.charge_item_name IS '料金項目名称';
R50: COMMENT ON COLUMN rms_contract_fee_information.charge_item_classification_code IS '料金項目分類コード';
R51: COMMENT ON COLUMN rms_contract_fee_information.charge_item_classification_code_name IS '料金項目分類コード名';
R52: COMMENT ON COLUMN rms_contract_fee_information.display_sort_control IS '表示ソート制御';
R53: COMMENT ON COLUMN rms_contract_fee_information.contract_start_date IS '契約開始日';
R54: COMMENT ON COLUMN rms_contract_fee_information.contract_end_date IS '契約終了日';
... R77: COMMENT ON COLUMN rms_contract_fee_information.point_used_flag_name IS 'ポイント利用済みflg名';

Sheet (COP)支払情報
F2: 種別 | G2: DWH公開名 | H2: 旧DWH公開名 | I2: 統合テーブルID | J2: スキーマ
F3: ビュー | G3: b_cop_支払情報 | H3: B_支払情報_[権限] | I3: V000604 | J3: user_l2id | K3: cop_payment_information
F4: データ概要：
F5: 支払い方法（窓口、郵便、口振、クレジットなど）を管理。
K6: ="DROP TABLE IF EXISTS "&K3&" CASCADE;" -> DROP TABLE IF EXISTS cop_payment_information CASCADE; | R6: DROP TABLE IF EXISTS cop_payment_information CASCADE;
K7: ="CREATE TABLE IF NOT EXISTS "&K3&" (" -> CREATE TABLE IF NOT EXISTS cop_payment_information ( | N7: ="COMMENT ON TABLE "&K3&" IS '"&G3&"';" -> COMMENT ON TABLE cop_payment_information IS 'b_cop_支払情報'; | R7: CREATE TABLE IF NOT EXISTS cop_payment_information (
A8: pk | B8: SEQ | C8: 項目名 | D8: TYPE | E8: 桁 | F8: 仮名化 | G8: 項目説明およびリスト値 | H8: コードリファレンスリンク | I8: 備考 | J8: 更新日 | K8: id BIGINT GENERATED BY DEFAULT AS IDENTITY, | N8: ="COMMENT ON COLUMN "&$K$3&".id IS 'id';" -> COMMENT ON COLUMN cop_payment_information.id IS 'id'; | R8: id BIGINT GENERATED BY DEFAULT AS IDENTITY,
A9: ○ | B9: 1 | C9: レコード通番 | D9: DECIMAL | E9: 38,0 | F9: － | G9: レコード通番 | I9: X3対応(桁変更) | K9: record_serial_number | L9: =D9&"("&E9&")," -> DECIMAL(38,0), | N9: ="COMMENT ON COLUMN "&$K$3&"."&$K9&" IS '"&C9&"';" -> COMMENT ON COLUMN cop_payment_information.record_serial_number IS 'レコード通番'; | R9: record_serial_number DECIMAL(38,0),
B10: 2 | C10: 請求グループid | D10: VARCHAR | E10: 40 | F10: ○ | G10: 請求グループID(B#) | I10: ・H制御Viewでは仮名加工された値が表示されます | K10: billing_group_id | L10: =D10&"("&E10&")," -> VARCHAR(40), | N10: ="COMMENT ON COLUMN "&$K$3&"."&$K10&" IS '"&C10&"';" -> COMMENT ON COLUMN cop_payment_information.billing_group_id IS '請求グループid'; | R10: billing_group_id VARCHAR(40),
B11: 3 | C11: 有効開始日 | D11: VARCHAR | E11: 16 | F11: － | G11: 有効開始日(YYYYMMDD) | J11: ★項目説明修正(2025/6/24) | K11: effective_start_date | L11: =D11&"("&E11&")," -> VARCHAR(16), | N11: ="COMMENT ON COLUMN "&$K$3&"."&$K11&" IS '"&C11&"';" -> COMMENT ON COLUMN cop_payment_information.effective_start_date IS '有効開始日'; | R11: effective_start_date VARCHAR(16),
G12: 前提：データ投入方法は、システム連携・フロント(GINIE等)経由の2種類がある | L12: =D12&"("&E12&")," -> (), | N12: ="COMMENT ON COLUMN "&$K$3&"."&$K12&" IS '"&C12&"';" -> COMMENT ON COLUMN cop_payment_information. IS ''; | R12: effective_end_date VARCHAR(16),
L13: =D13&"("&E13&")," -> (), | N13: ="COMMENT ON COLUMN "&$K$3&"."&$K13&" IS '"&C13&"';" -> COMMENT ON COLUMN cop_payment_information. IS ''; | R13: deletion_indicator VARCHAR(2),
G14: ・システム連携のデータ | L14: =D14&"("&E14&")," -> (), | N14: ="COMMENT ON COLUMN "&$K$3&"."&$K14&" IS '"&C14&"';" -> COMMENT ON COLUMN cop_payment_information. IS ''; | R14: created_date VARCHAR(16),
G15: 99991231：最新(=継続中)のデータ | L15: =D15&"("&E15&")," -> (), | N15: ="COMMENT ON COLUMN "&$K$3&"."&$K15&" IS '"&C15&"';" -> COMMENT ON COLUMN cop_payment_information. IS ''; | R15: new_code VARCHAR(4),
L16: =D16&"("&E16&")," -> (), | N16: ="COMMENT ON COLUMN "&$K$3&"."&$K16&" IS '"&C16&"';" -> COMMENT ON COLUMN cop_payment_information. IS ''; | R16: billing_payment_method_code VARCHAR(4),
G17: ・GINIE→CCOC経由の支払方法更新時のデータ | L17: =D17&"("&E17&")," -> (), | N17: ="COMMENT ON COLUMN "&$K$3&"."&$K17&" IS '"&C17&"';" -> COMMENT ON COLUMN cop_payment_information. IS ''; | R17: reseller_company_id VARCHAR(10),
G18: 10年後：新規/譲渡でB#新設時で、支払方法が口振/クレでPay easy利用なし（承認IND：N）の場合 | L18: =D18&"("&E18&")," -> (), | N18: ="COMMENT ON COLUMN "&$K$3&"."&$K18&" IS '"&C18&"';" -> COMMENT ON COLUMN cop_payment_information. IS ''; | R18: financial_institution_type_code VARCHAR(4),
G19: 29991230：情報変更（支払方法変更）で、口振/クレでPay easy利用なし（承認IND：N）の場合 | L19: =D19&"("&E19&")," -> (), | N19: ="COMMENT ON COLUMN "&$K$3&"."&$K19&" IS '"&C19&"';" -> COMMENT ON COLUMN cop_payment_information. IS ''; | R19: invoice_type_code VARCHAR(4),
G20: 29991231：B#変更なしの承継で、支払方法が口振/クレでPay easy利用なし（承認IND：N）の場合 | L20: =D20&"("&E20&")," -> (), | N20: ="COMMENT ON COLUMN "&$K$3&"."&$K20&" IS '"&C20&"';" -> COMMENT ON COLUMN cop_payment_information. IS ''; | R20: bank_id VARCHAR(8),
L21: =D21&"("&E21&")," -> (), | N21: ="COMMENT ON COLUMN "&$K$3&"."&$K21&" IS '"&C21&"';" -> COMMENT ON COLUMN cop_payment_information. IS ''; | R21: bank_branch_id VARCHAR(6),
G22: ・その他のデータ | L22: =D22&"("&E22&")," -> (), | N22: ="COMMENT ON COLUMN "&$K$3&"."&$K22&" IS '"&C22&"';" -> COMMENT ON COLUMN cop_payment_information. IS ''; | R22: post_office_id VARCHAR(8),
G23: 上記以外の直近ではない未来日付：直投されたデータ | L23: =D23&"("&E23&")," -> (), | N23: ="COMMENT ON COLUMN "&$K$3&"."&$K23&" IS '"&C23&"';" -> COMMENT ON COLUMN cop_payment_information. IS ''; | R23: credit_card_company_id VARCHAR(10),
B24: 4 | C24: 有効終了日 | D24: VARCHAR | E24: 16 | F24: － | G24: 有効終了日(YYYYMMDD) | J24: ★項目説明修正(2025/6/24) | K24: effective_end_date | L24: =D24&"("&E24&")," -> VARCHAR(16), | N24: ="COMMENT ON COLUMN "&$K$3&"."&$K24&" IS '"&C24&"';" -> COMMENT ON COLUMN cop_payment_information.effective_end_date IS '有効終了日'; | R24: application_number VARCHAR(24),
G25: 前提：データ投入方法は、システム連携・フロント(GINIE等)経由の2種類がある | L25: =D25&"("&E25&")," -> (), | N25: ="COMMENT ON COLUMN "&$K$3&"."&$K25&" IS '"&C25&"';" -> COMMENT ON COLUMN cop_payment_information. IS ''; | R25: invoice_automatic_change_indicator VARCHAR(2),
L26: =D26&"("&E26&")," -> (), | N26: ="COMMENT ON COLUMN "&$K$3&"."&$K26&" IS '"&C26&"';" -> COMMENT ON COLUMN cop_payment_information. IS ''; | R26: CONSTRAINT pk_cop_payment_information PRIMARY KEY (id));
G27: ・システム連携のデータ | L27: =D27&"("&E27&")," -> (), | N27: ="COMMENT ON COLUMN "&$K$3&"."&$K27&" IS '"&C27&"';" -> COMMENT ON COLUMN cop_payment_information. IS ''; | R27: COMMENT ON TABLE cop_payment_information IS 'b_cop_支払情報';
G28: 99991231：最新(=継続中)のデータ | L28: =D28&"("&E28&")," -> (), | N28: ="COMMENT ON COLUMN "&$K$3&"."&$K28&" IS '"&C28&"';" -> COMMENT ON COLUMN cop_payment_information. IS ''; | R28: COMMENT ON COLUMN cop_payment_information.id IS 'id';
L29: =D29&"("&E29&")," -> (), | N29: ="COMMENT ON COLUMN "&$K$3&"."&$K29&" IS '"&C29&"';" -> COMMENT ON COLUMN cop_payment_information. IS ''; | R29: COMMENT ON COLUMN cop_payment_information.record_serial_number IS 'レコード通番';
G30: ・GINIE→CCOC経由の支払方法更新時のデータ | L30: =D30&"("&E30&")," -> (), | N30: ="COMMENT ON COLUMN "&$K$3&"."&$K30&" IS '"&C30&"';" -> COMMENT ON COLUMN cop_payment_information. IS ''; | R30: COMMENT ON COLUMN cop_payment_information.billing_group_id IS '請求グループid';
G31: 10年後：新規/譲渡でB#新設時で、支払方法が口振/クレでPay easy利用なし（承認IND：N）の場合 | L31: =D31&"("&E31&")," -> (), | N31: ="COMMENT ON COLUMN "&$K$3&"."&$K31&" IS '"&C31&"';" -> COMMENT ON COLUMN cop_payment_information. IS ''; | R31: COMMENT ON COLUMN cop_payment_information.effective_start_date IS '有効開始日';
G32: 29991230：情報変更（支払方法変更）で、口振/クレでPay easy利用なし（承認IND：N）の場合 | L32: =D32&"("&E32&")," -> (), | N32: ="COMMENT ON COLUMN "&$K$3&"."&$K32&" IS '"&C32&"';" -> COMMENT ON COLUMN cop_payment_information. IS ''; | R32: COMMENT ON COLUMN cop_payment_information.effective_end_date IS '有効終了日';
G33: 29991231：B#変更なしの承継で、支払方法が口振/クレでPay easy利用なし（承認IND：N）の場合 | L33: =D33&"("&E33&")," -> (), | N33: ="COMMENT ON COLUMN "&$K$3&"."&$K33&" IS '"&C33&"';" -> COMMENT ON COLUMN cop_payment_information. IS ''; | R33: COMMENT ON COLUMN cop_payment_information.deletion_indicator IS '削除インジケータ';
